<?xml version="1.0" encoding="UTF-8"?>
<!-- Generated by org.testng.reporters.JUnitReportReporter -->
<testsuite hostname="DESKTOP-285KDFR" failures="1" tests="9" name="rerunTestCases.TestCases2" time="0.078" errors="1" timestamp="2022-10-10T22:18:16 IST" skipped="6">
  <testcase classname="rerunTestCases.TestCases2" name="loginFlipkart" time="0.016"/>
  <system-out/>
  <testcase classname="rerunTestCases.TestCases2" name="loginMyntra" time="0.016">
    <skipped/>
  </testcase> <!-- loginMyntra -->
  <system-out/>
  <testcase classname="rerunTestCases.TestCases2" name="loginMyntra" time="0.015">
    <failure message="expected [true] but found [false]" type="java.lang.AssertionError">
      <![CDATA[java.lang.AssertionError: expected [true] but found [false]
at org.testng.Assert.fail(Assert.java:99)
at org.testng.Assert.failNotEquals(Assert.java:1037)
at org.testng.Assert.assertTrue(Assert.java:45)
at org.testng.Assert.assertTrue(Assert.java:55)
at rerunTestCases.TestCases2.loginMyntra(TestCases2.java:19)
at java.base/jdk.internal.reflect.NativeMethodAccessorImpl.invoke0(Native Method)
at java.base/jdk.internal.reflect.NativeMethodAccessorImpl.invoke(NativeMethodAccessorImpl.java:62)
at java.base/jdk.internal.reflect.DelegatingMethodAccessorImpl.invoke(DelegatingMethodAccessorImpl.java:43)
at java.base/java.lang.reflect.Method.invoke(Method.java:566)
at org.testng.internal.MethodInvocationHelper.invokeMethod(MethodInvocationHelper.java:133)
at org.testng.internal.TestInvoker.invokeMethod(TestInvoker.java:598)
at org.testng.internal.TestInvoker.retryFailed(TestInvoker.java:213)
at org.testng.internal.MethodRunner.runInSequence(MethodRunner.java:58)
at org.testng.internal.TestInvoker$MethodInvocationAgent.invoke(TestInvoker.java:824)
at org.testng.internal.TestInvoker.invokeTestMethods(TestInvoker.java:146)
at org.testng.internal.TestMethodWorker.invokeTestMethods(TestMethodWorker.java:146)
at org.testng.internal.TestMethodWorker.run(TestMethodWorker.java:128)
at java.base/java.util.ArrayList.forEach(ArrayList.java:1541)
at org.testng.TestRunner.privateRun(TestRunner.java:794)
at org.testng.TestRunner.run(TestRunner.java:596)
at org.testng.SuiteRunner.runTest(SuiteRunner.java:377)
at org.testng.SuiteRunner.runSequentially(SuiteRunner.java:371)
at org.testng.SuiteRunner.privateRun(SuiteRunner.java:332)
at org.testng.SuiteRunner.run(SuiteRunner.java:276)
at org.testng.SuiteRunnerWorker.runSuite(SuiteRunnerWorker.java:53)
at org.testng.SuiteRunnerWorker.run(SuiteRunnerWorker.java:96)
at org.testng.TestNG.runSuitesSequentially(TestNG.java:1212)
at org.testng.TestNG.runSuitesLocally(TestNG.java:1134)
at org.testng.TestNG.runSuites(TestNG.java:1063)
at org.testng.TestNG.run(TestNG.java:1031)
at org.testng.remote.AbstractRemoteTestNG.run(AbstractRemoteTestNG.java:115)
at org.testng.remote.RemoteTestNG.initAndRun(RemoteTestNG.java:251)
at org.testng.remote.RemoteTestNG.main(RemoteTestNG.java:77)
]]>
    </failure>
  </testcase> <!-- loginMyntra -->
  <system-out/>
  <testcase classname="rerunTestCases.TestCases2" name="loginMyntra" time="0.000">
    <skipped/>
  </testcase> <!-- loginMyntra -->
  <system-out/>
  <testcase classname="rerunTestCases.TestCases2" name="loginAmazon" time="0.000">
    <skipped/>
  </testcase> <!-- loginAmazon -->
  <system-out/>
  <testcase classname="rerunTestCases.TestCases2" name="loginAmazon" time="0.016">
    <skipped/>
  </testcase> <!-- loginAmazon -->
  <system-out/>
  <testcase classname="rerunTestCases.TestCases2" name="loginAmazon" time="0.000">
    <skipped/>
  </testcase> <!-- loginAmazon -->
  <system-out/>
  <testcase classname="rerunTestCases.TestCases2" name="loginMyntra" time="0.015">
    <skipped/>
  </testcase> <!-- loginMyntra -->
  <system-out/>
  <testcase classname="rerunTestCases.TestCases2" name="loginAmazon" time="0.000">
    <error message="/ by zero" type="java.lang.ArithmeticException">
      <![CDATA[java.lang.ArithmeticException: / by zero
at rerunTestCases.TestCases2.loginAmazon(TestCases2.java:10)
at java.base/jdk.internal.reflect.NativeMethodAccessorImpl.invoke0(Native Method)
at java.base/jdk.internal.reflect.NativeMethodAccessorImpl.invoke(NativeMethodAccessorImpl.java:62)
at java.base/jdk.internal.reflect.DelegatingMethodAccessorImpl.invoke(DelegatingMethodAccessorImpl.java:43)
at java.base/java.lang.reflect.Method.invoke(Method.java:566)
at org.testng.internal.MethodInvocationHelper.invokeMethod(MethodInvocationHelper.java:133)
at org.testng.internal.TestInvoker.invokeMethod(TestInvoker.java:598)
at org.testng.internal.TestInvoker.retryFailed(TestInvoker.java:213)
at org.testng.internal.MethodRunner.runInSequence(MethodRunner.java:58)
at org.testng.internal.TestInvoker$MethodInvocationAgent.invoke(TestInvoker.java:824)
at org.testng.internal.TestInvoker.invokeTestMethods(TestInvoker.java:146)
at org.testng.internal.TestMethodWorker.invokeTestMethods(TestMethodWorker.java:146)
at org.testng.internal.TestMethodWorker.run(TestMethodWorker.java:128)
at java.base/java.util.ArrayList.forEach(ArrayList.java:1541)
at org.testng.TestRunner.privateRun(TestRunner.java:794)
at org.testng.TestRunner.run(TestRunner.java:596)
at org.testng.SuiteRunner.runTest(SuiteRunner.java:377)
at org.testng.SuiteRunner.runSequentially(SuiteRunner.java:371)
at org.testng.SuiteRunner.privateRun(SuiteRunner.java:332)
at org.testng.SuiteRunner.run(SuiteRunner.java:276)
at org.testng.SuiteRunnerWorker.runSuite(SuiteRunnerWorker.java:53)
at org.testng.SuiteRunnerWorker.run(SuiteRunnerWorker.java:96)
at org.testng.TestNG.runSuitesSequentially(TestNG.java:1212)
at org.testng.TestNG.runSuitesLocally(TestNG.java:1134)
at org.testng.TestNG.runSuites(TestNG.java:1063)
at org.testng.TestNG.run(TestNG.java:1031)
at org.testng.remote.AbstractRemoteTestNG.run(AbstractRemoteTestNG.java:115)
at org.testng.remote.RemoteTestNG.initAndRun(RemoteTestNG.java:251)
at org.testng.remote.RemoteTestNG.main(RemoteTestNG.java:77)
]]>
    </error>
  </testcase> <!-- loginAmazon -->
  <system-out/>
</testsuite> <!-- rerunTestCases.TestCases2 -->
